Workbook

Sheet Отдельно Озон Nimba
A1: ID | B1: Articles | C1: ID_mix | D1: Articles_cabinet
A2: 1 | B2: парео синий шиф | C2: 1 | D2: парео синий шифон
A3: 2 | B3: парео малина шиф | C3: =VLOOKUP(Шаблон_Ozon!A4,Шаблон_Ozon!A:D,3,0) -> 2 | D3: парео малина шиф
A4: 3 | B4: парео оранж шиф | C4: =VLOOKUP(Шаблон_Ozon!A6,Шаблон_Ozon!A:D,3,0) -> 3 | D4: парео оранж шифон
A5: 4 | B5: парео черн шиф | C5: =VLOOKUP(Шаблон_Ozon!A8,Шаблон_Ozon!A:D,3,0) -> 4 | D5: парео черный шифон
A6: 5 | B6: парео фуксия шиф | C6: =VLOOKUP(Шаблон_Ozon!A10,Шаблон_Ozon!A:D,3,0) -> 5 | D6: парео фуксия
A7: 6 | B7: парео зеленый шиф | C7: =VLOOKUP(Шаблон_Ozon!A12,Шаблон_Ozon!A:D,3,0) -> 6 | D7: туник шифон зелёный
A8: 7 | B8: парео сиреневый шиф | C8: =VLOOKUP(Шаблон_Ozon!A15,Шаблон_Ozon!A:D,3,0) -> 8 | D8: туник шифон белый
A9: 8 | B9: парео белый шиф | C9: =VLOOKUP(Шаблон_Ozon!A17,Шаблон_Ozon!A:D,3,0) -> 9 | D9: Шифон.голубой
A10: 9 | B10: парео голубой шиф | C10: =VLOOKUP(Шаблон_Ozon!A18,Шаблон_Ozon!A:D,3,0) -> 9 | D10: туник шифон голубой
A11: 10 | B11: парео салатовый | C11: =VLOOKUP(Шаблон_Ozon!A20,Шаблон_Ozon!A:D,3,0) -> 10 | D11: парео салатовый
A12: 11 | B12: парео желтый шиф | C12: =VLOOKUP(Шаблон_Ozon!A22,Шаблон_Ozon!A:D,3,0) -> 11 | D12: парео желтый шиф
A13: 12 | B13: хлопок зеленый | C13: =VLOOKUP(Шаблон_Ozon!A23,Шаблон_Ozon!A:D,3,0) -> 11 | D13: туника шифон жёлтый
A14: 13 | B14: хлопок синий | C14: =VLOOKUP(Шаблон_Ozon!A25,Шаблон_Ozon!A:D,3,0) -> 12 | D14: парео хлопок зелёный
A15: 14 | B15: парео хлопок желтый | C15: =VLOOKUP(Шаблон_Ozon!A26,Шаблон_Ozon!A:D,3,0) -> 12 | D15: туника хлоп зелен
A16: 15 | B16: парео хлопок розовый | C16: =VLOOKUP(Шаблон_Ozon!A28,Шаблон_Ozon!A:D,3,0) -> 13 | D16: парео хлопок синий
A17: 16 | B17: парео хлопок черный | C17: =VLOOKUP(Шаблон_Ozon!A30,Шаблон_Ozon!A:D,3,0) -> 14 | D17: туник хлоп желт
A18: 17 | B18: парео хлопок белый | C18: =VLOOKUP(Шаблон_Ozon!A31,Шаблон_Ozon!A:D,3,0) -> 15 | D18: туник хлопок роза
A19: 18 | B19: парео хлопок голубой | C19: =VLOOKUP(Шаблон_Ozon!A33,Шаблон_Ozon!A:D,3,0) -> 16 | D19: парео черный хлопок
A20: 19 | B20: синий шиф без воротника | C20: =VLOOKUP(Шаблон_Ozon!A35,Шаблон_Ozon!A:D,3,0) -> 17 | D20: парео белый хлоп
A21: 20 | B21: черный шиф без воротника | C21: =VLOOKUP(Шаблон_Ozon!A37,Шаблон_Ozon!A:D,3,0) -> 18 | D21: парео хлопок голубой
A22: 21 | B22: зеленый шиф без воротника | C22: =VLOOKUP(Шаблон_Ozon!A39,Шаблон_Ozon!A:D,3,0) -> 19 | D22: парео без ворот синий
A23: 22 | B23: малина шиф без воротника | C23: =VLOOKUP(Шаблон_Ozon!A41,Шаблон_Ozon!A:D,3,0) -> 20 | D23: парео без ворот черный
A24: 23 | B24: парео зебра черно белая | C24: =VLOOKUP(Шаблон_Ozon!A43,Шаблон_Ozon!A:D,3,0) -> 21 | D24: парео без ворот зелен
A25: 24 | B25: зебра бело черная | C25: 22 | D25: парео без ворот малина
A26: 25 | B26: 1туника леопард/пятна | C26: 23 | D26: парео зебра черн бел
A27: 26 | B27: 2туника синие волны | C27: 24 | D27: парео зебра бел чер
A28: 27 | B28: 3туника светло зеленая | C28: 25 | D28: туника леопар. пятн
A29: 28 | B29: 4туника черный лист | C29: 25 | D29: халат леопар. пятн
A30: 29 | B30: 5туника зеленый лист | C30: 26 | D30: туника синяя полоска
A31: 30 | B31: 6туника зеленая волна | C31: 26 | D31: халат синяя полоска
A32: 31 | B32: 7туника синяя ракушка | C32: 27 | D32: туника светл. зелёная
A33: 32 | B33: длинная жираф ЧЕРНО/белый | C33: 27 | D33: халат светл. зелёный
A34: 33 | B34: длинная БЕЛО/черный жираф | C34: 28 | D34: туника черный лист
A35: 34 | B35: длинная жираф зелено/черный | C35: 28 | D35: халат черный лист
A36: 35 | B36: длинная жираф коричнево/черный | C36: 29 | D36: туника зелен лист
... A45: 44 | B45: парео квадрат черный шиф | C45: 35 | D45: парео жираф длинный корич. черн
C46: 36 | D46: пареожираф корот. чер-бел
C47: 37 | D47: жираф короткая/бел/чер
C48: 38 | D48: накидка детская белый 92-110
...

Sheet Отдельно Озон Galioni
A1: ID | B1: Articles | C1: ID_mix | D1: Articles_cabinet
A2: 1 | B2: парео синий шиф | C2: 1 | D2: накидка синий шиф
A3: 2 | B3: парео малина шиф | C3: 2 | D3: накидка ярко красный неон шифон
A4: 3 | B4: парео оранж шиф | C4: 3 | D4: накидка оранж шиф
A5: 4 | B5: парео черн шиф | C5: 4 | D5: накидка черн шиф
A6: 5 | B6: парео фуксия шиф | C6: 5 | D6: накидка фуксия
A7: 6 | B7: парео зеленый шиф | C7: 6 | D7: накидка зеленый шиф
A8: 7 | B8: парео сиреневый шиф | C8: 7 | D8: накидка сирень шиф
A9: 8 | B9: парео белый шиф | C9: 8 | D9: накидка белый шиф
A10: 9 | B10: парео голубой шиф | C10: 9 | D10: накидка голуб шиф
A11: 10 | B11: парео салатовый | C11: 10 | D11: накидка салат
A12: 11 | B12: парео желтый шиф | C12: 11 | D12: накидка желтый шиф
A13: 12 | B13: хлопок зеленый | C13: 12 | D13: накидка зеленый хлопок
... A45: 44 | B45: парео квадрат черный шиф | C45: 40 | D45: туника голубой детская 112-130
C46: 40 | D46: туника голубой детская 132-152
C47: 41 | D47: туника/фиолет/детская

Sheet Отдельно Озон AGNIA
A1: ID | B1: Articles | C1: ID_mix | D1: Articles_cabinet
A2: 1 | B2: парео синий шиф | C2: 4 | D2: шифон черный
A3: 2 | B3: парео малина шиф | C3: 6 | D3: парео зелен.шифон
A4: 3 | B4: парео оранж шиф | C4: 9 | D4: голубой шифон
A5: 4 | B5: парео черн шиф | C5: 10 | D5: салатовый шифон
A6: 5 | B6: парео фуксия шиф | C6: 12 | D6: хлопок зеленый
A7: 6 | B7: парео зеленый шиф | C7: 13 | D7: хлопок синий
A8: 7 | B8: парео сиреневый шиф | C8: 14 | D8: хлопок желтый
A9: 8 | B9: парео белый шиф | C9: 16 | D9: хлопок черный
A10: 9 | B10: парео голубой шиф | C10: 17 | D10: хлопок белый
A11: 10 | B11: парео салатовый | C11: 18 | D11: хлопок голубой
A12: 11 | B12: парео желтый шиф | C12: 19 | D12: шифон синий без ворот
A13: 12 | B13: хлопок зеленый | C13: 25 | D13: леопард пятна туник
... A29: 28 | B29: 4туника черный лист | C29: 40 | D29: детск. туника.голубой152
A30: 29 | B30: 5туника зеленый лист
A31: 30 | B31: 6туника зеленая волна
A32: 31 | B32: 7туника синяя ракушка
A33: 32 | B33: длинная жираф ЧЕРНО/белый
A34: 33 | B34: длинная БЕЛО/черный жираф
A35: 34 | B35: длинная жираф зелено/черный
A36: 35 | B36: длинная жираф коричнево/черный
A37: 36 | B37: короткая жираф ЧЕРНО/белый
A38: 37 | B38: короткая БЕЛО/черный жираф
A39: 38 | B39: детская туника белая
A40: 39 | B40: детская туника розовая
A41: 40 | B41: детская туника голубая
... A45: 44 | B45: парео квадрат черный шиф

Sheet Отдельно ВБ Nimba
A1: ID | B1: Articles | C1: ID_mix | D1: Articles_cabinet
A2: 1 | B2: парео синий шиф | C2: 1 | D2: парео синий
A3: 2 | B3: парео малина шиф | C3: 2 | D3: парео малиновый
A4: 3 | B4: парео оранж шиф | C4: 3 | D4: парео оранж
A5: 4 | B5: парео черн шиф | C5: 4 | D5: парео черный
A6: 5 | B6: парео фуксия шиф | C6: 5 | D6: парео фуксия
A7: 6 | B7: парео зеленый шиф | C7: 6 | D7: парео зеленый
A8: 7 | B8: парео сиреневый шиф | C8: 7 | D8: парео сирень2
A9: 8 | B9: парео белый шиф | C9: 8 | D9: парео белый
A10: 9 | B10: парео голубой шиф | C10: 9 | D10: парео голубой
A11: 10 | B11: парео салатовый | C11: 10 | D11: парео салатовый
A12: 11 | B12: парео желтый шиф | C12: 11 | D12: парео желтый
A13: 12 | B13: хлопок зеленый | C13: 12 | D13: парео/хлопок/зеленый
... A45: 44 | B45: парео квадрат черный шиф | C45: 30 | D45: парео\зеленая полоска
C46: 30 | D46: Туника/зелен/полоска
C47: 30 | D47: Халат/зелен/полоска
C48: 31 | D48: Туника/синия/ракушка
C49: 31 | D49: Халат/синий/ракушка
C50: 31 | D50: Парео/синия/ракушка
C51: 32 | D51: жираф длин. чер/бел
C52: 33 | D52: жираф длин бел/черн
C53: 34 | D53: жираф длин зелен/черн
C54: 35 | D54: жираф длин корич/черн
C55: 36 | D55: жираф корот. черн/бел
C56: 37 | D56: жираф корот. бел/черн
C57: 38 | D57: туника/детская/белый
... C63: 44 | D63: парео квадр/черный шиф

Sheet Отдельно ВБ Galioni
A1: ID | B1: Articles | C1: ID_mix | D1: Articles_cabinet
A2: 1 | B2: парео синий шиф | C2: 1 | D2: парео синий шифон
A3: 2 | B3: парео малина шиф | C3: 2 | D3: парео малина
A4: 3 | B4: парео оранж шиф | C4: 3 | D4: парео оранж
A5: 4 | B5: парео черн шиф | C5: 4 | D5: парео черный 1
A6: 5 | B6: парео фуксия шиф | C6: 6 | D6: парео зеленый
A7: 6 | B7: парео зеленый шиф | C7: 7 | D7: парео сирень
A8: 7 | B8: парео сиреневый шиф | C8: 8 | D8: парео белый
A9: 8 | B9: парео белый шиф | C9: 9 | D9: парео голубой
A10: 9 | B10: парео голубой шиф | C10: 10 | D10: парео салатовый
A11: 10 | B11: парео салатовый | C11: 11 | D11: парео желтый
A12: 11 | B12: парео желтый шиф | C12: 12 | D12: парео хлопок/зелен
A13: 12 | B13: хлопок зеленый | C13: 13 | D13: парео хлопок/синий
... A45: 44 | B45: парео квадрат черный шиф | C45: 38 | D45: парео\детская\белая\112\130
C46: 38 | D46: парео/детск/белое/132/152
C47: 39 | D47: парео/детс/розовый/92/110
C48: 39 | D48: парео\детская\розовый\112\130
C49: 39 | D49: парео/детск/розов/132/152
C50: 40 | D50: парео/детск/голубой/92/110
C51: 40 | D51: парео/детская/голубая/112/130
C52: 41 | D52: парео\детская\фиолет
C53: 42 | D53: парео голуб.шиф/Квадр
C54: 43 | D54: парео синий шиф/Квадр
C55: 44 | D55: парео черн шиф/Квадр

Sheet Отдельно ВБ AGNIA
A1: ID | B1: Articles | C1: ID_mix | D1: Articles_cabinet
A2: 1 | B2: парео синий шиф | C2: 1 | D2: Парео синий шифон
A3: 2 | B3: парео малина шиф | C3: 3 | D3: Парео оран шиф
A4: 3 | B4: парео оранж шиф | C4: 4 | D4: Черн шиф.
A5: 4 | B5: парео черн шиф | C5: 6 | D5: Парео зеленый шифон
A6: 5 | B6: парео фуксия шиф | C6: 9 | D6: шифон голубой
A7: 6 | B7: парео зеленый шиф | C7: 10 | D7: шифон салатовый
A8: 7 | B8: парео сиреневый шиф | C8: 13 | D8: хлопок синий
A9: 8 | B9: парео белый шиф | C9: 16 | D9: хлопок черн
A10: 9 | B10: парео голубой шиф | C10: 17 | D10: хлопок белый
A11: 10 | B11: парео салатовый | C11: 18 | D11: хлопок голубой
A12: 11 | B12: парео желтый шиф | C12: 19 | D12: без ворот синий ш
A13: 12 | B13: хлопок зеленый | C13: 25 | D13: леопард пятна
... A21: 20 | B21: черный шиф без воротника | C21: 40 | D21: муслин голубой
A22: 21 | B22: зеленый шиф без воротника
A23: 22 | B23: малина шиф без воротника
A24: 23 | B24: парео зебра черно белая
A25: 24 | B25: зебра бело черная
A26: 25 | B26: 1туника леопард/пятна
A27: 26 | B27: 2туника синие волны
A28: 27 | B28: 3туника светло зеленая
A29: 28 | B29: 4туника черный лист
A30: 29 | B30: 5туника зеленый лист
A31: 30 | B31: 6туника зеленая волна
A32: 31 | B32: 7туника синяя ракушка
A33: 32 | B33: длинная жираф ЧЕРНО/белый
... A45: 44 | B45: парео квадрат черный шиф

Sheet Cебестоимость
A1: ID | B1: Articles | C1: Себестоимость
A2: 1 | B2: парео синий шиф | C2: 603
A3: 2 | B3: парео малина шиф | C3: 603
A4: 3 | B4: парео оранж шиф | C4: 603
A5: 4 | B5: парео черн шиф | C5: 603
A6: 5 | B6: парео фуксия шиф | C6: 603
A7: 6 | B7: парео зеленый шиф | C7: 603
A8: 7 | B8: парео сиреневый шиф | C8: 603
A9: 8 | B9: парео белый шиф | C9: 603
A10: 9 | B10: парео голубой шиф | C10: 603
A11: 10 | B11: парео салатовый | C11: 603
A12: 11 | B12: парео желтый шиф | C12: 603
A13: 12 | B13: хлопок зеленый | C13: 712
... A45: 44 | B45: парео квадрат черный шиф | C45: 320

Sheet Шаблон_Ozon
A1: ID | B1: Articles | C1: ID_mix | D1: Mixed_Articles
A2: 1 | B2: парео синий шиф | C2: 1 | D2: накидка синий шиф
A3: 2 | B3: парео малина шиф | C3: 2 | D3: накидка ярко красный неон шифон
A4: 3 | B4: парео оранж шиф | C4: 2 | D4: парео малина шиф
A5: 4 | B5: парео черн шиф | C5: 3 | D5: накидка оранж шиф
A6: 5 | B6: парео фуксия шиф | C6: 3 | D6: парео оранж шифон
A7: 6 | B7: парео зеленый шиф | C7: 4 | D7: накидка черн шиф
A8: 7 | B8: парео сиреневый шиф | C8: 4 | D8: парео черный шифон
A9: 8 | B9: парео белый шиф | C9: 5 | D9: накидка фуксия
A10: 9 | B10: парео голубой шиф | C10: 5 | D10: парео фуксия
A11: 10 | B11: парео салатовый | C11: 6 | D11: накидка зеленый шиф
A12: 11 | B12: парео желтый шиф | C12: 6 | D12: туник шифон зелёный
A13: 12 | B13: хлопок зеленый | C13: 7 | D13: накидка сирень шиф
... A44: 43 | B44: парео квадрат черный шиф | C44: 22 | D44: накидка без ворот малина шиф
C45: 22 | D45: парео без ворот малина
C46: 23 | D46: накидка зебра черн-бел вискоза
C47: 23 | D47: парео зебра черн бел
C48: 24 | D48: накидка зебра бело-черн вискоза
C49: 24 | D49: парео зебра бел чер
C50: 25 | D50: Туника/леопард/пятн
C51: 25 | D51: туника леопар. пятн
C52: 25 | D52: халат леопар. пятн
C53: 26 | D53: Туника/син/волны
C54: 26 | D54: туника синяя полоска
C55: 26 | D55: халат синяя полоска
C56: 27 | D56: Туника/зеленый
... C91: 43 | D91: парео квадрат/черный шиф
D92: парео леопар/син
D93: парео леопард/оранж

Sheet Шаблон_WB
A1: ID | B1: Articles | C1: ID_mix | D1: Mixed_Articles
A2: 1 | B2: парео синий шиф | C2: 1 | D2: парео синий
A3: 2 | B3: парео малина шиф | C3: 1 | D3: парео синий шифон
A4: 3 | B4: парео оранж шиф | C4: 2 | D4: парео малиновый
A5: 4 | B5: парео черн шиф | C5: 2 | D5: парео малина
A6: 5 | B6: парео фуксия шиф | C6: 3 | D6: парео оранж
A7: 6 | B7: парео зеленый шиф | C7: 3 | D7: парео оранж
A8: 7 | B8: парео сиреневый шиф | C8: 4 | D8: парео черный
A9: 8 | B9: парео белый шиф | C9: 4 | D9: парео черный 1
A10: 9 | B10: парео голубой шиф | C10: 5 | D10: парео фуксия
A11: 10 | B11: парео салатовый | C11: 6 | D11: парео зеленый
A12: 11 | B12: парео желтый шиф | C12: 6 | D12: парео зеленый
A13: 12 | B13: хлопок зеленый | C13: 7 | D13: парео сирень2
... A44: 43 | B44: парео квадрат черный шиф | C44: 21 | D44: парео/без/зеленое
C45: 21 | D45: парео/без ворот/зеленый
C46: 22 | D46: парео/без ворот/малина
C47: 22 | D47: парео/малина/без воротника
C48: 23 | D48: парео/зебра/черн/бел
C49: 23 | D49: парео хлопок/черно-белое
C50: 24 | D50: парео/зебра/бел/черн
C51: 24 | D51: парео хлопок бело-черное
C52: 25 | D52: парео/леопар/пятн
C53: 25 | D53: Туника/леопар/пятн
C54: 25 | D54: Халат/леопар/пятн
C55: 25 | D55: парео/леопард/пятн
C56: 25 | D56: Халат/леопард
... C110: 43 | D110: парео черн шиф/Квадр
